[2021-07-18 16:30:55,413] {taskinstance.py:896} INFO - Dependencies all met for <TaskInstance: treino-01.Hello_Bash 2021-07-18T19:10:00+00:00 [queued]>
[2021-07-18 16:30:55,424] {taskinstance.py:896} INFO - Dependencies all met for <TaskInstance: treino-01.Hello_Bash 2021-07-18T19:10:00+00:00 [queued]>
[2021-07-18 16:30:55,424] {taskinstance.py:1087} INFO - 
--------------------------------------------------------------------------------
[2021-07-18 16:30:55,425] {taskinstance.py:1088} INFO - Starting attempt 2 of 2
[2021-07-18 16:30:55,425] {taskinstance.py:1089} INFO - 
--------------------------------------------------------------------------------
[2021-07-18 16:30:55,442] {taskinstance.py:1107} INFO - Executing <Task(BashOperator): Hello_Bash> on 2021-07-18T19:10:00+00:00
[2021-07-18 16:30:55,446] {standard_task_runner.py:52} INFO - Started process 14874 to run task
[2021-07-18 16:30:55,454] {standard_task_runner.py:76} INFO - Running: ['airflow', 'tasks', 'run', 'treino-01', 'Hello_Bash', '2021-07-18T19:10:00+00:00', '--job-id', '24', '--pool', 'default_pool', '--raw', '--subdir', 'DAGS_FOLDER/treino01.py', '--cfg-path', '/tmp/tmpei_8h8of', '--error-file', '/tmp/tmpvknlx4cu']
[2021-07-18 16:30:55,455] {standard_task_runner.py:77} INFO - Job 24: Subtask Hello_Bash
[2021-07-18 16:30:55,493] {logging_mixin.py:104} INFO - Running <TaskInstance: treino-01.Hello_Bash 2021-07-18T19:10:00+00:00 [running]> on host julio-VirtualBox
[2021-07-18 16:30:55,526] {taskinstance.py:1300} INFO - Exporting the following env vars:
AIRFLOW_CTX_DAG_EMAIL=julio.zeferino@bex-team.com,julioszeferino@outlook.com.br
AIRFLOW_CTX_DAG_OWNER=Neylson - IGTI
AIRFLOW_CTX_DAG_ID=treino-01
AIRFLOW_CTX_TASK_ID=Hello_Bash
AIRFLOW_CTX_EXECUTION_DATE=2021-07-18T19:10:00+00:00
AIRFLOW_CTX_DAG_RUN_ID=scheduled__2021-07-18T19:10:00+00:00
[2021-07-18 16:30:55,526] {subprocess.py:52} INFO - Tmp dir root location: 
 /tmp
[2021-07-18 16:30:55,527] {subprocess.py:63} INFO - Running command: ['bash', '-c', '\n    echo "Hello Airflow from Bash!\n    ']
[2021-07-18 16:30:55,538] {subprocess.py:74} INFO - Output:
[2021-07-18 16:30:55,539] {subprocess.py:78} INFO - bash: -c: line 1: unexpected EOF while looking for matching `"'
[2021-07-18 16:30:55,539] {subprocess.py:78} INFO - bash: -c: line 3: syntax error: unexpected end of file
[2021-07-18 16:30:55,539] {subprocess.py:82} INFO - Command exited with return code 1
[2021-07-18 16:30:55,544] {taskinstance.py:1501} ERROR - Task failed with exception
Traceback (most recent call last):
  File "/home/julio/anaconda3/lib/python3.8/site-packages/airflow/models/taskinstance.py", line 1157, in _run_raw_task
    self._prepare_and_execute_task_with_callbacks(context, task)
  File "/home/julio/anaconda3/lib/python3.8/site-packages/airflow/models/taskinstance.py", line 1331, in _prepare_and_execute_task_with_callbacks
    result = self._execute_task(context, task_copy)
  File "/home/julio/anaconda3/lib/python3.8/site-packages/airflow/models/taskinstance.py", line 1361, in _execute_task
    result = task_copy.execute(context=context)
  File "/home/julio/anaconda3/lib/python3.8/site-packages/airflow/operators/bash.py", line 176, in execute
    raise AirflowException('Bash command failed. The command returned a non-zero exit code.')
airflow.exceptions.AirflowException: Bash command failed. The command returned a non-zero exit code.
[2021-07-18 16:30:55,546] {taskinstance.py:1544} INFO - Marking task as FAILED. dag_id=treino-01, task_id=Hello_Bash, execution_date=20210718T191000, start_date=20210718T193055, end_date=20210718T193055
[2021-07-18 16:30:55,565] {logging_mixin.py:104} WARNING - /home/julio/anaconda3/lib/python3.8/site-packages/airflow/utils/email.py:102 PendingDeprecationWarning: Fetching SMTP credentials from configuration variables will be deprecated in a future release. Please set credentials using a connection instead.
[2021-07-18 16:30:55,566] {configuration.py:365} WARNING - section/key [smtp/smtp_user] not found in config
[2021-07-18 16:30:55,566] {email.py:208} INFO - Email alerting: attempt 1
[2021-07-18 16:30:56,249] {email.py:220} INFO - Sent an alert email to ['julio.zeferino@bex-team.com', 'julioszeferino@outlook.com.br']
[2021-07-18 16:30:56,815] {configuration.py:365} WARNING - section/key [smtp/smtp_user] not found in config
[2021-07-18 16:30:56,815] {email.py:208} INFO - Email alerting: attempt 1
[2021-07-18 16:30:57,496] {email.py:220} INFO - Sent an alert email to ['julio.zeferino@bex-team.com', 'julioszeferino@outlook.com.br']
[2021-07-18 16:30:58,056] {taskinstance.py:1557} ERROR - Failed to send email to: ['julio.zeferino@bex-team.com', 'julioszeferino@outlook.com.br']
Traceback (most recent call last):
  File "/home/julio/anaconda3/lib/python3.8/site-packages/airflow/models/taskinstance.py", line 1157, in _run_raw_task
    self._prepare_and_execute_task_with_callbacks(context, task)
  File "/home/julio/anaconda3/lib/python3.8/site-packages/airflow/models/taskinstance.py", line 1331, in _prepare_and_execute_task_with_callbacks
    result = self._execute_task(context, task_copy)
  File "/home/julio/anaconda3/lib/python3.8/site-packages/airflow/models/taskinstance.py", line 1361, in _execute_task
    result = task_copy.execute(context=context)
  File "/home/julio/anaconda3/lib/python3.8/site-packages/airflow/operators/bash.py", line 176, in execute
    raise AirflowException('Bash command failed. The command returned a non-zero exit code.')
airflow.exceptions.AirflowException: Bash command failed. The command returned a non-zero exit code.

During handling of the above exception, another exception occurred:

Traceback (most recent call last):
  File "/home/julio/anaconda3/lib/python3.8/site-packages/airflow/models/taskinstance.py", line 1896, in email_alert
    send_email(self.task.email, subject, html_content)
  File "/home/julio/anaconda3/lib/python3.8/site-packages/airflow/utils/email.py", line 55, in send_email
    return backend(
  File "/home/julio/anaconda3/lib/python3.8/site-packages/airflow/utils/email.py", line 102, in send_email_smtp
    send_mime_email(e_from=smtp_mail_from, e_to=recipients, mime_msg=msg, conn_id=conn_id, dryrun=dryrun)
  File "/home/julio/anaconda3/lib/python3.8/site-packages/airflow/utils/email.py", line 221, in send_mime_email
    conn.sendmail(e_from, e_to, mime_msg.as_string())
  File "/home/julio/anaconda3/lib/python3.8/smtplib.py", line 869, in sendmail
    raise SMTPSenderRefused(code, resp, from_addr)
smtplib.SMTPSenderRefused: (530, b'5.7.0 Authentication Required. Learn more at\n5.7.0  https://support.google.com/mail/?p=WantAuthError x10sm9518039pfh.56 - gsmtp', 'julioszeferino@gmail.com')

During handling of the above exception, another exception occurred:

Traceback (most recent call last):
  File "/home/julio/anaconda3/lib/python3.8/site-packages/airflow/models/taskinstance.py", line 1555, in handle_failure
    self.email_alert(error)
  File "/home/julio/anaconda3/lib/python3.8/site-packages/airflow/models/taskinstance.py", line 1898, in email_alert
    send_email(self.task.email, subject, html_content_err)
  File "/home/julio/anaconda3/lib/python3.8/site-packages/airflow/utils/email.py", line 55, in send_email
    return backend(
  File "/home/julio/anaconda3/lib/python3.8/site-packages/airflow/utils/email.py", line 102, in send_email_smtp
    send_mime_email(e_from=smtp_mail_from, e_to=recipients, mime_msg=msg, conn_id=conn_id, dryrun=dryrun)
  File "/home/julio/anaconda3/lib/python3.8/site-packages/airflow/utils/email.py", line 221, in send_mime_email
    conn.sendmail(e_from, e_to, mime_msg.as_string())
  File "/home/julio/anaconda3/lib/python3.8/smtplib.py", line 869, in sendmail
    raise SMTPSenderRefused(code, resp, from_addr)
smtplib.SMTPSenderRefused: (530, b'5.7.0 Authentication Required. Learn more at\n5.7.0  https://support.google.com/mail/?p=WantAuthError y6sm13740434pjr.48 - gsmtp', 'julioszeferino@gmail.com')
[2021-07-18 16:30:58,083] {local_task_job.py:149} INFO - Task exited with return code 1
