[2021-07-18 16:38:48,652] {taskinstance.py:896} INFO - Dependencies all met for <TaskInstance: treino-01.Hello_Bash 2021-07-18T19:32:00+00:00 [queued]>
[2021-07-18 16:38:48,657] {taskinstance.py:896} INFO - Dependencies all met for <TaskInstance: treino-01.Hello_Bash 2021-07-18T19:32:00+00:00 [queued]>
[2021-07-18 16:38:48,657] {taskinstance.py:1087} INFO - 
--------------------------------------------------------------------------------
[2021-07-18 16:38:48,660] {taskinstance.py:1088} INFO - Starting attempt 2 of 2
[2021-07-18 16:38:48,661] {taskinstance.py:1089} INFO - 
--------------------------------------------------------------------------------
[2021-07-18 16:38:48,676] {taskinstance.py:1107} INFO - Executing <Task(BashOperator): Hello_Bash> on 2021-07-18T19:32:00+00:00
[2021-07-18 16:38:48,678] {standard_task_runner.py:52} INFO - Started process 15853 to run task
[2021-07-18 16:38:48,697] {standard_task_runner.py:76} INFO - Running: ['airflow', 'tasks', 'run', 'treino-01', 'Hello_Bash', '2021-07-18T19:32:00+00:00', '--job-id', '39', '--pool', 'default_pool', '--raw', '--subdir', 'DAGS_FOLDER/treino01.py', '--cfg-path', '/tmp/tmp_meytzh3', '--error-file', '/tmp/tmpax_5x329']
[2021-07-18 16:38:48,697] {standard_task_runner.py:77} INFO - Job 39: Subtask Hello_Bash
[2021-07-18 16:38:48,754] {logging_mixin.py:104} INFO - Running <TaskInstance: treino-01.Hello_Bash 2021-07-18T19:32:00+00:00 [running]> on host julio-VirtualBox
[2021-07-18 16:38:48,794] {taskinstance.py:1300} INFO - Exporting the following env vars:
AIRFLOW_CTX_DAG_EMAIL=julio.zeferino@bex-data.com
AIRFLOW_CTX_DAG_OWNER=Neylson - IGTI
AIRFLOW_CTX_DAG_ID=treino-01
AIRFLOW_CTX_TASK_ID=Hello_Bash
AIRFLOW_CTX_EXECUTION_DATE=2021-07-18T19:32:00+00:00
AIRFLOW_CTX_DAG_RUN_ID=scheduled__2021-07-18T19:32:00+00:00
[2021-07-18 16:38:48,796] {subprocess.py:52} INFO - Tmp dir root location: 
 /tmp
[2021-07-18 16:38:48,796] {subprocess.py:63} INFO - Running command: ['bash', '-c', '\n    echo "Hello Airflow from Bash!\n    ']
[2021-07-18 16:38:48,811] {subprocess.py:74} INFO - Output:
[2021-07-18 16:38:48,811] {subprocess.py:78} INFO - bash: -c: line 1: unexpected EOF while looking for matching `"'
[2021-07-18 16:38:48,811] {subprocess.py:78} INFO - bash: -c: line 3: syntax error: unexpected end of file
[2021-07-18 16:38:48,812] {subprocess.py:82} INFO - Command exited with return code 1
[2021-07-18 16:38:48,817] {taskinstance.py:1501} ERROR - Task failed with exception
Traceback (most recent call last):
  File "/home/julio/anaconda3/lib/python3.8/site-packages/airflow/models/taskinstance.py", line 1157, in _run_raw_task
    self._prepare_and_execute_task_with_callbacks(context, task)
  File "/home/julio/anaconda3/lib/python3.8/site-packages/airflow/models/taskinstance.py", line 1331, in _prepare_and_execute_task_with_callbacks
    result = self._execute_task(context, task_copy)
  File "/home/julio/anaconda3/lib/python3.8/site-packages/airflow/models/taskinstance.py", line 1361, in _execute_task
    result = task_copy.execute(context=context)
  File "/home/julio/anaconda3/lib/python3.8/site-packages/airflow/operators/bash.py", line 176, in execute
    raise AirflowException('Bash command failed. The command returned a non-zero exit code.')
airflow.exceptions.AirflowException: Bash command failed. The command returned a non-zero exit code.
[2021-07-18 16:38:48,820] {taskinstance.py:1544} INFO - Marking task as FAILED. dag_id=treino-01, task_id=Hello_Bash, execution_date=20210718T193200, start_date=20210718T193848, end_date=20210718T193848
[2021-07-18 16:38:48,849] {logging_mixin.py:104} WARNING - /home/julio/anaconda3/lib/python3.8/site-packages/airflow/utils/email.py:102 PendingDeprecationWarning: Fetching SMTP credentials from configuration variables will be deprecated in a future release. Please set credentials using a connection instead.
[2021-07-18 16:38:48,849] {email.py:208} INFO - Email alerting: attempt 1
[2021-07-18 16:39:18,953] {email.py:208} INFO - Email alerting: attempt 1
[2021-07-18 16:39:48,983] {taskinstance.py:1557} ERROR - Failed to send email to: ['julio.zeferino@bex-data.com']
Traceback (most recent call last):
  File "/home/julio/anaconda3/lib/python3.8/site-packages/airflow/models/taskinstance.py", line 1157, in _run_raw_task
    self._prepare_and_execute_task_with_callbacks(context, task)
  File "/home/julio/anaconda3/lib/python3.8/site-packages/airflow/models/taskinstance.py", line 1331, in _prepare_and_execute_task_with_callbacks
    result = self._execute_task(context, task_copy)
  File "/home/julio/anaconda3/lib/python3.8/site-packages/airflow/models/taskinstance.py", line 1361, in _execute_task
    result = task_copy.execute(context=context)
  File "/home/julio/anaconda3/lib/python3.8/site-packages/airflow/operators/bash.py", line 176, in execute
    raise AirflowException('Bash command failed. The command returned a non-zero exit code.')
airflow.exceptions.AirflowException: Bash command failed. The command returned a non-zero exit code.

During handling of the above exception, another exception occurred:

Traceback (most recent call last):
  File "/home/julio/anaconda3/lib/python3.8/site-packages/airflow/models/taskinstance.py", line 1896, in email_alert
    send_email(self.task.email, subject, html_content)
  File "/home/julio/anaconda3/lib/python3.8/site-packages/airflow/utils/email.py", line 55, in send_email
    return backend(
  File "/home/julio/anaconda3/lib/python3.8/site-packages/airflow/utils/email.py", line 102, in send_email_smtp
    send_mime_email(e_from=smtp_mail_from, e_to=recipients, mime_msg=msg, conn_id=conn_id, dryrun=dryrun)
  File "/home/julio/anaconda3/lib/python3.8/site-packages/airflow/utils/email.py", line 210, in send_mime_email
    conn = _get_smtp_connection(smtp_host, smtp_port, smtp_timeout, smtp_ssl)
  File "/home/julio/anaconda3/lib/python3.8/site-packages/airflow/utils/email.py", line 244, in _get_smtp_connection
    else smtplib.SMTP(host=host, port=port, timeout=timeout)
  File "/home/julio/anaconda3/lib/python3.8/smtplib.py", line 253, in __init__
    (code, msg) = self.connect(host, port)
  File "/home/julio/anaconda3/lib/python3.8/smtplib.py", line 337, in connect
    self.sock = self._get_socket(host, port, self.timeout)
  File "/home/julio/anaconda3/lib/python3.8/smtplib.py", line 308, in _get_socket
    return socket.create_connection((host, port), timeout,
  File "/home/julio/anaconda3/lib/python3.8/socket.py", line 808, in create_connection
    raise err
  File "/home/julio/anaconda3/lib/python3.8/socket.py", line 796, in create_connection
    sock.connect(sa)
OSError: [Errno 101] Network is unreachable

During handling of the above exception, another exception occurred:

Traceback (most recent call last):
  File "/home/julio/anaconda3/lib/python3.8/site-packages/airflow/models/taskinstance.py", line 1555, in handle_failure
    self.email_alert(error)
  File "/home/julio/anaconda3/lib/python3.8/site-packages/airflow/models/taskinstance.py", line 1898, in email_alert
    send_email(self.task.email, subject, html_content_err)
  File "/home/julio/anaconda3/lib/python3.8/site-packages/airflow/utils/email.py", line 55, in send_email
    return backend(
  File "/home/julio/anaconda3/lib/python3.8/site-packages/airflow/utils/email.py", line 102, in send_email_smtp
    send_mime_email(e_from=smtp_mail_from, e_to=recipients, mime_msg=msg, conn_id=conn_id, dryrun=dryrun)
  File "/home/julio/anaconda3/lib/python3.8/site-packages/airflow/utils/email.py", line 210, in send_mime_email
    conn = _get_smtp_connection(smtp_host, smtp_port, smtp_timeout, smtp_ssl)
  File "/home/julio/anaconda3/lib/python3.8/site-packages/airflow/utils/email.py", line 244, in _get_smtp_connection
    else smtplib.SMTP(host=host, port=port, timeout=timeout)
  File "/home/julio/anaconda3/lib/python3.8/smtplib.py", line 253, in __init__
    (code, msg) = self.connect(host, port)
  File "/home/julio/anaconda3/lib/python3.8/smtplib.py", line 337, in connect
    self.sock = self._get_socket(host, port, self.timeout)
  File "/home/julio/anaconda3/lib/python3.8/smtplib.py", line 308, in _get_socket
    return socket.create_connection((host, port), timeout,
  File "/home/julio/anaconda3/lib/python3.8/socket.py", line 808, in create_connection
    raise err
  File "/home/julio/anaconda3/lib/python3.8/socket.py", line 796, in create_connection
    sock.connect(sa)
OSError: [Errno 101] Network is unreachable
[2021-07-18 16:39:49,004] {local_task_job.py:149} INFO - Task exited with return code 1
